Workbook

Sheet Sheet1- Corp. Profile & Datas
A12: Consolidated Balance Sheets- Pfizer Inc. | H12: Consolidated Statements of Income- Pfizer Inc.
A13: (In Millions, Except Per Share Data) | B13: As of December 31, | H13: (In Millions, Except Per Share Data) | I13: As of December 31,
B14: 2022 | C14: 2021 | I14: 2022 | J14: 2021 | K14: 2020
A15: Assets | H15: Revenues | I15: 100330 | J15: 81288 | K15: 41651
A16: Cash and cash equivalents | B16: 416 | C16: 1944 | H16: Costs and expenses:
A17: Short-term investments | B17: 22316 | C17: 29125 | H17: Cost of sales | I17: 34344 | J17: 30821 | K17: 8484
A18: Trade accounts receivable, less allowance for doubtful accounts: 2022—$449; 2021—$492 | B18: 10952 | C18: 11479 | H18: Selling, informational and administrative expenses | I18: 13677 | J18: 12703 | K18: 11597
A19: Inventories | B19: 8981 | C19: 9059 | H19: Research and development expenses | I19: 11428 | J19: 10360 | K19: 8709
A20: Current tax assets | B20: 3577 | C20: 4266 | H20: Acquired in-process research and development expenses | I20: 953 | J20: 3469 | K20: 684
A21: Other current assets | B21: 5017 | C21: 3820 | H21: Amortization of intangible assets | I21: 3609 | J21: 3700 | K21: 3348
A22: Total current assets | B22: 51259 | C22: 59693 | H22: Restructuring charges and certain acquisition-related costs | I22: 1375 | J22: 802 | K22: 579
A23: Equity-method investments | B23: 11033 | C23: 16472 | H23: Other (income)/deductions––net | I23: 217 | J23: -4878 | K23: 1213
A24: Long-term investments | B24: 4036 | C24: 5054 | H24: Income from continuing operations before provision/(benefit) for taxes on income | I24: 34729 | J24: 24311 | K24: 7036
A25: Property, plant and equipment | B25: 16274 | C25: 14882 | H25: Provision/(benefit) for taxes on income | I25: 3328 | J25: 1852 | K25: 370
A26: Identifiable intangible assets | B26: 43370 | C26: 25146 | H26: Income from continuing operations | I26: 31401 | J26: 22459 | K26: 6666
A27: Goodwill | B27: 51375 | C27: 49208 | H27: Discontinued operations––net of tax | I27: 6 | J27: -434 | K27: 2529
A28: Noncurrent deferred tax assets and other noncurrent tax assets | B28: 6693 | C28: 3341 | H28: Net income before allocation to noncontrolling interests | I28: 31407 | J28: 22025 | K28: 9195
... A30: Total assets | B30: 197205 | C30: 181476 | H30: Net income attributable to Pfizer Inc. common shareholders | I30: 31372 | J30: 21979 | K30: 9159
A32: Liabilities and Equity | H32: Earnings per common share– Basic:
A33: Short-term borrowings, including current portion of long-term debt: 2022—$2,560; 2021—$1,636 | B33: 2945 | C33: 2241 | H33: Income from continuing operations attributable to Pfizer Inc. common shareholders | I33: 5.59 | J33: 4 | K33: 1.19
A34: Trade accounts payable | B34: 6809 | C34: 5578 | H34: Discontinued operations––net of tax | I34: — | J34: -0.08 | K34: 0.46
A35: Dividends payable | B35: 2303 | C35: 2249 | H35: Net income attributable to Pfizer Inc. common shareholders | I35: 5.59 | J35: 3.92 | K35: 1.65
A36: Income taxes payable | B36: 1587 | C36: 1266
A37: Accrued compensation and related items | B37: 3407 | C37: 3332 | H37: Earnings per common share––Diluted:
A38: Deferred revenues | B38: 2520 | C38: 3067 | H38: Income from continuing operations attributable to Pfizer Inc. common shareholders | I38: 5.47 | J38: 3.93 | K38: 1.18
A39: Other current liabilities | B39: 22568 | C39: 24939 | H39: Discontinued operations––net of tax | I39: — | J39: -0.08 | K39: 0.45
A40: Total current liabilities | B40: 42138 | C40: 42671 | H40: Net income attributable to Pfizer Inc. common shareholders | I40: 5.47 | J40: 3.85 | K40: 1.63
A41: Long-term debt | B41: 32884 | C41: 36195 | H41: Weighted-average shares––basic | I41: 5608 | J41: 5601 | K41: 5555
A42: Pension and postretirement benefit obligations | B42: 2250 | C42: 3724 | H42: Weighted-average shares––diluted | I42: 5733 | J42: 5708 | K42: 5632
A43: Noncurrent deferred tax liabilities | B43: 1023 | C43: 349
A44: Other taxes payable | B44: 9812 | C44: 11331
A45: Other noncurrent liabilities | B45: 13180 | C45: 9743
A46: Total Liabilities | B46: 101288 | C46: 104013
A48: Commitments and Contingencies
A49: Preferred stock, no par value, at stated value; 27 shares authorized; no shares issued or outstanding at December 31, 2022 and December 31, 2021 | B49: — | C49: —
A50: Common stock, $0.05 par value; 12,000 shares authorized; issued: 2022—9,519; 2021—9,471 | B50: 476 | C50: 473
A51: Additional paid-in capital | B51: 91802 | C51: 90591
A52: Treasury stock, shares at cost: 2022—3,903; 2021—3,851 | B52: -113969 | C52: -111361
A53: Retained earnings | B53: 125656 | C53: 103394
A54: Accumulated other comprehensive loss | B54: -8304 | C54: -5897
...

Sheet Sheet2- Cashflow Statement
A1: Cash Flow Statement- Pfizer Inc.
A2: (In Millions) | B2: As of December 31,
B3: 2022 | C3: 2021 | D3: 2020
A4: Operating Activities
A5: Net income before allocation to noncontrolling interests | B5: 31401 | C5: 22025 | D5: 9195
A6: Adjustments to reconcile net income before allocation to noncontrolling interests to net cash provided by operating activities:
A7: Depreciation and amortization | B7: 5064 | C7: 5191 | D7: 4681
A8: Deferred taxes from continuing operations | B8: -3764 | C8: -4293 | D8: -1575
A9: Other Funds | B9: 1022 | C9: -3147 | D9: 2409
A10: Other changes in assets and liabilities, net of acquisitions and divestitures:
A11: Trade accounts receivable | B11: 261 | C11: -3811 | D11: -1275
A12: Inventories | B12: 592 | C12: -1125 | D12: -778
A13: Other Assets/Liabilities | B13: -6500 | C13: 16498 | D13: 1391
A14: Trade accounts payable | B14: 1191 | C14: 1242 | D14: 355
A15: Net cash provided by operating activities | B15: 29267 | C15: 32580 | D15: 14403
A17: Investing Activities
A18: Purchases of property, plant and equipment | B18: -3236 | C18: -2711 | D18: -2226
A19: Purchases of short-term investments | B19: -36384 | C19: -38457 | D19: -13805
A20: Proceeds from redemptions/sales of short-term investments | B20: 44821 | C20: 27447 | D20: 11087
A21: Net (purchases of)/proceeds from redemptions/sales of short-term investments with original maturities of three months or less | B21: -483 | C21: -8088 | D21: 920
A22: Purchases of long-term investments | B22: -1913 | C22: -1068 | D22: -597
A23: Proceeds from redemptions/sales of long-term investments | B23: 641 | C23: 649 | D23: 723
A24: Acquisitions of businesses, net of cash acquired | B24: -22997 | C24: — | D24: —
A25: Dividend received from the Consumer Healthcare JV | B25: 3960 | C25: — | D25: —
A26: Other investing activities, net | B26: -192 | C26: -317 | D26: -374
A27: Net cash provided by/(used in) investing activities | B27: -15783 | C27: -22546 | D27: -4271
A29: Financing Activities
A30: Proceeds from short-term borrowings | B30: 3891 | C30: — | D30: 12352
A31: Payments on short-term borrowings | B31: -3887 | C31: — | D31: -22197
A32: Net (payments on)/proceeds from short-term borrowings with original maturities of three months or less | B32: -222 | C32: -96 | D32: -4129
A33: Proceeds from issuances of long-term debt | B33: — | C33: 997 | D33: 5222
A34: Payments on long-term debt | B34: -3298 | C34: -2004 | D34: -4003
A35: Purchases of common stock | B35: -2000 | C35: — | D35: —
A36: Cash dividends paid | B36: -8983 | C36: -8729 | D36: -8440
A37: Other financing activities, net | B37: -335 | C37: 16 | D37: -444
A38: Net cash provided by/(used in) financing activities from continuing operations | B38: -14834 | C38: -9816 | D38: -21640
A39: Net cash provided by/(used in) financing activities from discontinued operations | B39: — | C39: — | D39: 11991
A40: Net cash provided by/(used in) financing activities | B40: -14834 | C40: -9816 | D40: -9649

Sheet Sheet3- Ratios & Balance Sheet
A1: Common Size Balance Sheets- Pfizer Inc. | E1: Input Data (In Millions) | F1: 2022 | G1: 2021
A2: (In Millions, Except Per Share Data) | B2: As of December 31, | E2: =A5 -> Current Assets | F2: {=B12:C12} -> 51259 | G2: 59693
B3: 2022 | C3: 2021 | E3: =A25 -> Current Liabilities | F3: {=B33:C33} -> 42138 | G3: 42671
A4: Assets | E4: =A9 -> Inventories | F4: {=B9:C9} -> 8981 | G4: 9059
A5: Current Assets | E5: Total Debt | F5: =(B26+B35)-2560 -> 33269 | G5: =(C26+C35)-1636 -> 36800
A6: Cash and cash equivalents | B6: 416 | C6: 1944 | E6: =A22 -> Total assets | F6: =B22 -> 197205 | G6: =C22 -> 181476
A7: Short-term investments | B7: 22316 | C7: 29125 | E7: Total Shareholders Equity | F7: {='Sheet1- Corp. Profile & Datas'!B57:C57} -> 95916 | G7: 77462
A8: Trade accounts receivable, less allowance for doubtful accounts: 2022—$449; 2021—$492 | B8: 10952 | C8: 11479 | E8: COGS | F8: {='Sheet1- Corp. Profile & Datas'!I17:J17} -> 34344 | G8: 30821
A9: Inventories | B9: 8981 | C9: 9059 | E9: Total Shares Outstanding | F9: {='Sheet1- Corp. Profile & Datas'!I41:J41} -> 5608 | G9: 5601
A10: Current tax assets | B10: 3577 | C10: 4266 | E10: Revenue | F10: {='Sheet1- Corp. Profile & Datas'!I15:J15} -> 100330 | G10: 81288
A11: Other current assets | B11: 5017 | C11: 3820 | E11: Gross Profit | F11: ='Sheet1- Corp. Profile & Datas'!I15-'Sheet1- Corp. Profile & Datas'!I17 -> 65986 | G11: ='Sheet1- Corp. Profile & Datas'!J15-'Sheet1- Corp. Profile & Datas'!J17 -> 50467
A12: Total current assets | B12: 51259 | C12: 59693 | E12: Net Income | F12: {='Sheet1- Corp. Profile & Datas'!I30:J30} -> 31372 | G12: 21979
A13: Long-Term Assets
A14: Equity-method investments | B14: 11033 | C14: 16472 | E14: Financial Ratios | F14: Formula | G14: 2022 | H14: 2021
A15: Long-term investments | B15: 4036 | C15: 5054 | E15: Current Ratio | F15: Current Assets/Current Liabilities | G15: =F2/F3 -> 1.2164555 | H15: =G2/G3 -> 1.3989126
A16: Property, plant and equipment | B16: 16274 | C16: 14882 | E16: Quick Ratio | F16: (Current assets - Inventory) / Current Liabilities | G16: =(F2-F4)/F3 -> 1.0033224 | H16: =(G2-G4)/G3 -> 1.1866139
A17: Identifiable intangible assets | B17: 43370 | C17: 25146 | E17: Debt to Asset Ratio | F17: Total Debt / Total assets | G17: =F5/F6 -> 0.16870262 | H17: =G5/G6 -> 0.20278164
A18: Goodwill | B18: 51375 | C18: 49208 | E18: Debt to Equity Ratio | F18: Total Debt / Total Shareholders' Equity | G18: =F5/F7 -> 0.34685558 | H18: =G5/G7 -> 0.47507165
A19: Noncurrent deferred tax assets and other noncurrent tax assets | B19: 6693 | C19: 3341 | E19: Asset Turnover Ratio | F19: Revenue / Total Assets | G19: =F10/F6 -> 0.50875992 | H19: =G10/G6 -> 0.447927
A20: Other noncurrent assets | B20: 13163 | C20: 7679 | E20: Inventory Turnover Ratio | F20: COGS/ Inventory | G20: =F8/F4 -> 3.824073 | H20: =G8/G4 -> 3.4022519
A21: Total Long-Term Assets | B21: =SUM(B14:B20) -> 145944 | C21: =SUM(C14:C20) -> 121782 | E21: Return on Assets Ratio | F21: Net Income / Total Assets | G21: =F12/F6 -> 0.15908319 | H21: =G12/G6 -> 0.12111243
A22: Total assets | B22: 197205 | C22: 181476 | E22: Return on Equity Ratio | F22: Net Income / Shareholders' Equity | G22: =F12/F7 -> 0.32707786 | H22: =G12/G7 -> 0.28373912
E23: EPS Ratio | F23: Net Income / Total Shares Outstanding | G23: =F12/F9 -> 5.5941512 | H23: =G12/G9 -> 3.9241207
A24: Liabilities and Equity | E24: Gross Margin Ratio | F24: Gross Profit / Revenue | G24: =F11/F10 -> 0.65768962 | H24: =G11/G10 -> 0.62084194
A25: Current Liabilities
A26: Short-term borrowings, including current portion of long-term debt: 2022—$2,560; 2021—$1,636 | B26: 2945 | C26: 2241
A27: Trade accounts payable | B27: 6809 | C27: 5578
A28: Dividends payable | B28: 2303 | C28: 2249
A29: Income taxes payable | B29: 1587 | C29: 1266
A30: Accrued compensation and related items | B30: 3407 | C30: 3332
A31: Deferred revenues | B31: 2520 | C31: 3067
A32: Other current liabilities | B32: 22568 | C32: 24939
A33: Total current liabilities | B33: 42138 | C33: 42671
A34: Long-term Liabilities
A35: Long-term debt | B35: 32884 | C35: 36195
A36: Pension and postretirement benefit obligations | B36: 2250 | C36: 3724
A37: Noncurrent deferred tax liabilities | B37: 1023 | C37: 349
A38: Other taxes payable | B38: 9812 | C38: 11331
A39: Other noncurrent liabilities | B39: 13180 | C39: 9743
A40: Total noncurrent liabilities | B40: =SUM(B35:B39) -> 59149 | C40: =SUM(C35:C39) -> 61342
...

Sheet Sheet4- Income Statement
A1: Simplified Income Statement- Pfizer Inc.
A2: (In Millions) | B2: As of December 31,
B3: 2022 | C3: 2021 | D3: % Change
A4: Revenues | B4: 100330 | C4: 81288 | D4: 0.23
A5: Cost of Goods Sold | B5: 34344 | C5: 30821 | D5: 0.11
A6: Gross Profit | B6: 65986 | C6: 50467 | D6: 0.31
A7: Operating Expenses
A8: Selling, informational and administrative expenses | B8: 13677 | C8: 12703
A9: Research and development expenses | B9: 11428 | C9: 10360
A10: Other Operating Expenses | B10: 6154 | C10: 3093
A11: Total Operating Expenses | B11: 31259 | C11: 26156 | D11: 0.2
A12: Income from continuing operations before provision/(benefit) for taxes on income | B12: 34729 | C12: 24311 | D12: 0.43
A13: Less: Income Taxes | B13: 3328 | C13: 1852
A14: Income from Continuing Operations (EAT) | B14: 31401 | C14: 22459 | D14: 0.4
A15: Discontinued operations––net of tax | B15: 6 | C15: -434
A16: Net income before allocation to noncontrolling interests | B16: 31407 | C16: 22025 | D16: 0.43
A17: Less: Net income attributable to noncontrolling interests | B17: 35 | C17: 45
A18: Net income attributable to Pfizer Inc. common shareholders | B18: 31372 | C18: 21979 | D18: 0.43

Sheet Sheet5- DOL
A1: DOL(Degree of Operating Leverage) =%Change in EBIT/%Change in Sales Revenue
B2: 2022 | C2: 2021 | D2: Changes in 2021 | E2: % Change in 2021-2022
A3: EBIT (Operating Profit) | B3: =34729+1238 -> 35967 | C3: =24311+1291 -> 25602 | D3: =B3-C3 -> 10365 | E3: =D3/C3 -> 0.40485118
A4: Sales Revenue | B4: 100330 | C4: 81288 | D4: =B4-C4 -> 19042 | E4: =D4/C4 -> 0.23425352
A5: DOL | E5: =(E3/E4)/100 -> 0.017282608
A9: DFL=EBIT/EBT
B10: 2022 | C10: 2021
A11: EBIT | B11: =34729+1238 -> 35967 | C11: ='Sheet1- Corp. Profile & Datas'!J24+1291 -> 25602
A12: EBT | B12: ='Sheet1- Corp. Profile & Datas'!I24 -> 34729 | C12: ='Sheet1- Corp. Profile & Datas'!J24 -> 24311
A13: DFL | B13: =B11/B12 -> 1.0356474 | C13: =C11/C12 -> 1.0531035
A16: DCL=DOL*DFL
A17: DOL | B17: =E5 -> 0.017282608
A18: DFL | B18: =AVERAGE(B13,C13) -> 1.0443755
A19: DCL | B19: =B17*B18 -> 0.018049533

Sheet Sheet6- CCC
A1: Cash Conversion Cycle- Pfizer Inc.
A2: (In Millions) | C2: As of December 31,
A3: Input Data | C3: 2022 | D3: 2021
A4: Inventory | C4: {='Sheet1- Corp. Profile & Datas'!B19:C19} -> 8981 | D4: 9059
A5: COGS | C5: {='Sheet4- Income Statement'!B5:C5} -> 34344 | D5: 30821
A6: Accounts Receivable | C6: ='Sheet3- Ratios & Balance Sheet'!B8-449 -> 10503 | D6: ='Sheet3- Ratios & Balance Sheet'!C8-492 -> 10987
A7: Accounts Payable | C7: {='Sheet3- Ratios & Balance Sheet'!B27:C27} -> 6809 | D7: 5578
A8: Average Inventory | B8: =AVERAGE('Sheet1- Corp. Profile & Datas'!B19:C19) -> 9020
A9: Average A/R | B9: =AVERAGE(C6:D6) -> 10745
A10: Average A/P | B10: =AVERAGE('Sheet1- Corp. Profile & Datas'!B34:C34) -> 6193.5
A11: Days Inventory Outstanding (DIO) | C11: =($B$8/C5)*365 -> 95.862451 | D11: =($B$8/D5)*365 -> 106.82003
A12: Days Sales Outstanding (DSO) | C12: =(B9/'Sheet1- Corp. Profile & Datas'!I15)*365 -> 39.090252 | D12: =(B9/'Sheet1- Corp. Profile & Datas'!J15)*365 -> 48.247281
A13: Days Payable Outstanding (DPO) | C13: =($B$10/C5)*365 -> 65.82307 | D13: =($B$10/D5)*365 -> 73.346987
A14: Cash Conversion Cycle | C14: =C11+C12-C13 -> 69.129633 | D14: =D11+D12-D13 -> 81.720319
